Workbook

Sheet Customers
A1: customer_id | B1: customer_unique_id | C1: customer_zip_code_prefix | D1: customer_city | E1: customer_state | F1: CustomerName | G1: Region | H1: ProvinceCity | I1: Email | J1: Phone | K1: RegisteredDate | L1: owner_id | M1: CustomerStatus | N1: CustomerSegment
A2: CUS00001 | B2: KH0001 | C2: 55000 | D2: Đà Nẵng | E2: DN | F2: Phạm Văn Hải | G2: Miền Trung | H2: Đà Nẵng | I2: kh0001@example.vn | J2: 0960 351 958 | K2: 45421 | L2: EMP001 | M2: Active | N2: Tiềm năng
A3: CUS00002 | B3: KH0002 | C3: 10000 | D3: Hà Nội | E3: HN | F3: Huỳnh Quốc Ngân | G3: Miền Bắc | H3: Hà Nội | I3: kh0002@example.vn | J3: 0931 115 592 | K3: 44962 | L3: EMP002 | M3: Active | N3: Tiềm năng
A4: CUS00003 | B4: KH0003 | C4: 56000 | D4: Quảng Nam | E4: QNA | F4: Võ Thị Mai | G4: Miền Trung | H4: Quảng Nam | I4: kh0003@example.vn | J4: 0956 296 045 | K4: 45643 | L4: EMP003 | M4: Active | N4: Tiềm năng cao
A5: CUS00004 | B5: KH0004 | C5: 25000 | D5: Thái Nguyên | E5: TN | F5: Trần Quốc Hạnh | G5: Miền Bắc | H5: Thái Nguyên | I5: kh0004@example.vn | J5: 0964 011 841 | K5: 45172 | L5: EMP004 | M5: Active | N5: Thông thường
A6: CUS00005 | B6: KH0005 | C6: 25000 | D6: Thái Nguyên | E6: TN | F6: Nguyễn Thị Hải | G6: Miền Bắc | H6: Thái Nguyên | I6: kh0005@example.vn | J6: 0928 246 491 | K6: 45040 | L6: EMP005 | M6: Active | N6: Thông thường
A7: CUS00006 | B7: KH0006 | C7: 25000 | D7: Thái Nguyên | E7: TN | F7: Trần Thị Hùng | G7: Miền Bắc | H7: Thái Nguyên | I7: kh0006@example.vn | J7: 0987 510 567 | K7: 45293 | L7: EMP006 | M7: Active | N7: Tiềm năng
A8: CUS00007 | B8: KH0007 | C8: 18000 | D8: Hải Phòng | E8: HP | F8: Nguyễn Ngọc Hùng | G8: Miền Bắc | H8: Hải Phòng | I8: kh0007@example.vn | J8: 0907 383 466 | K8: 45566 | L8: EMP007 | M8: Active | N8: Thông thường
A9: CUS00008 | B9: KH0008 | C9: 65000 | D9: Khánh Hòa | E9: KH | F9: Lê Ngọc Lan | G9: Miền Trung | H9: Khánh Hòa | I9: kh0008@example.vn | J9: 0961 580 884 | K9: 45263 | L9: EMP008 | M9: Active | N9: Tiềm năng
A10: CUS00009 | B10: KH0009 | C10: 16000 | D10: Bắc Ninh | E10: BN | F10: Huỳnh Quốc Bảo | G10: Miền Bắc | H10: Bắc Ninh | I10: kh0009@example.vn | J10: 0984 807 255 | K10: 45075 | L10: EMP001 | M10: Active | N10: Tiềm năng
A11: CUS00010 | B11: KH0010 | C11: 78000 | D11: Bà Rịa - Vũng Tàu | E11: BRVT | F11: Võ Minh Quân | G11: Miền Nam | H11: Bà Rịa - Vũng Tàu | I11: kh0010@example.vn | J11: 0944 109 467 | K11: 45177 | L11: EMP002 | M11: Active | N11: Thông thường
A12: CUS00011 | B12: KH0011 | C12: 18000 | D12: Hải Phòng | E12: HP | F12: Bùi Gia Long | G12: Miền Bắc | H12: Hải Phòng | I12: kh0011@example.vn | J12: 0914 998 960 | K12: 45428 | L12: EMP003 | M12: Active | N12: Chưa đủ dữ liệu
A13: CUS00012 | B13: KH0012 | C13: 20000 | D13: Quảng Ninh | E13: QN | F13: Trần Ngọc Lan | G13: Miền Bắc | H13: Quảng Ninh | I13: kh0012@example.vn | J13: 0915 503 813 | K13: 44992 | L13: EMP004 | M13: Active | N13: Tiềm năng
... A81: CUS00080 | B81: KH0080 | C81: 90000 | D81: Cần Thơ | E81: CT | F81: Nguyễn Quốc Châu | G81: Miền Nam | H81: Cần Thơ | I81: kh0080@example.vn | J81: 0966 439 551 | K81: 45055 | L81: EMP008 | M81: Active | N81: Chưa đủ dữ liệu

Sheet Products
A1: product_id | B1: product_category_name | C1: product_name_lenght | D1: product_description_lenght | E1: product_photos_qty | F1: product_weight_g | G1: product_length_cm | H1: product_height_cm | I1: product_width_cm | J1: Description | K1: ProductCategory | L1: ListPrice | M1: Currency | N1: ProductStatus
A2: SP001 | B2: dien_tu | C2: 18 | D2: 296 | E2: 1 | F2: 150 | G2: 8 | H2: 3 | I2: 8 | J2: Tai nghe Bluetooth | K2: Điện tử | L2: 440500 | M2: VNĐ | N2: Active
A3: SP002 | B3: dien_tu | C3: 15 | D3: 260 | E3: 2 | F3: 323 | G3: 15 | H3: 8 | I3: 19 | J3: Chuột không dây | K3: Điện tử | L3: 212300 | M3: VNĐ | N3: Active
A4: SP003 | B4: dien_tu | C4: 18 | D4: 296 | E4: 3 | F4: 496 | G4: 22 | H4: 13 | I4: 30 | J4: Loa Bluetooth mini | K4: Điện tử | L4: 380333 | M4: VNĐ | N4: Active
A5: SP004 | B5: dien_tu | C5: 16 | D5: 272 | E5: 4 | F5: 669 | G5: 29 | H5: 18 | I5: 41 | J5: Bàn phím cơ mini | K5: Điện tử | L5: 763867 | M5: VNĐ | N5: Active
A6: SP005 | B6: thoi_trang | C6: 14 | D6: 248 | E6: 5 | F6: 842 | G6: 36 | H6: 23 | I6: 52 | J6: Áo thun cotton | K6: Thời trang | L6: 177429 | M6: VNĐ | N6: Active
A7: SP006 | B7: thoi_trang | C7: 12 | D7: 224 | E7: 1 | F7: 1015 | G7: 43 | H7: 3 | I7: 13 | J7: Túi đeo chéo | K7: Thời trang | L7: 316571 | M7: VNĐ | N7: Active
A8: SP007 | B8: thoi_trang | C8: 12 | D8: 224 | E8: 2 | F8: 1188 | G8: 50 | H8: 8 | I8: 24 | J8: Mũ lưỡi trai | K8: Thời trang | L8: 142333 | M8: VNĐ | N8: Active
A9: SP008 | B9: thoi_trang | C9: 13 | D9: 236 | E9: 3 | F9: 1361 | G9: 57 | H9: 13 | I9: 35 | J9: Ví da nhỏ gọn | K9: Thời trang | L9: 279125 | M9: VNĐ | N9: Active
A10: SP009 | B10: my_pham | C10: 19 | D10: 308 | E10: 4 | F10: 1534 | G10: 9 | H10: 18 | I10: 46 | J10: Sữa rửa mặt dịu nhẹ | K10: Mỹ phẩm | L10: 159000 | M10: VNĐ | N10: Active
A11: SP010 | B11: my_pham | C11: 13 | D11: 236 | E11: 5 | F11: 1707 | G11: 16 | H11: 23 | I11: 57 | J11: Son dưỡng môi | K11: Mỹ phẩm | L11: 92800 | M11: VNĐ | N11: Active
A12: SP011 | B12: my_pham | C12: 20 | D12: 320 | E12: 1 | F12: 1880 | G12: 23 | H12: 3 | I12: 18 | J12: Kem chống nắng SPF50 | K12: Mỹ phẩm | L12: 275375 | M12: VNĐ | N12: Active
A13: SP012 | B13: my_pham | C13: 14 | D13: 248 | E13: 2 | F13: 2053 | G13: 30 | H13: 8 | I13: 29 | J13: Nước tẩy trang | K13: Mỹ phẩm | L13: 191455 | M13: VNĐ | N13: Active
... A41: SP040 | B41: phu_kien | C41: 20 | D41: 320 | E41: 5 | F41: 2097 | G41: 61 | H41: 23 | I41: 37 | J41: Túi chống sốc laptop | K41: Phụ kiện | L41: 254583 | M41: VNĐ | N41: Active

Sheet Orders
A1: order_id | B1: customer_id | C1: order_status | D1: order_purchase_timestamp | E1: order_approved_at | F1: order_delivered_carrier_date | G1: order_delivered_customer_date | H1: order_estimated_delivery_date | I1: CustomerID | J1: SalesChannel | K1: PaymentMethod | L1: Region | M1: ProvinceCity | N1: owner_id | O1: OrderSubtotal | P1: FreightTotal | Q1: DiscountTotal | R1: OrderTotal | S1: Currency | T1: IsValidForRFM
A2: DH00001 | B2: CUS00057 | C2: delivered | D2: 45905.313 | E2: 45905.397 | F2: 45907.313 | G2: 45911.313 | H2: 45913.313 | I2: KH0057 | J2: Cửa hàng | K2: Chuyển khoản | L2: Miền Bắc | M2: Thái Nguyên | N2: =IFERROR(VLOOKUP(I2,Customers!$B$2:$L$81,11,FALSE),"") -> EMP001 | O2: =SUMIF(OderItems!$A$2:$A$510,A2,OderItems!$L$2:$L$510) -> 3384000 | P2: =SUMIF(OderItems!$A$2:$A$510,A2,OderItems!$G$2:$G$510) -> 57000 | Q2: =SUMIF(OderItems!$A$2:$A$510,A2,OderItems!$K$2:$K$510) -> 0 | R2: =O2+P2-Q2 -> 3441000 | S2: VNĐ | T2: =AND(C2="delivered",I2<>"",R2>0) -> TRUE
A3: DH00002 | B3: CUS00056 | C3: delivered | D3: 46135.772 | E3: 46135.855 | F3: 46137.772 | G3: 46141.772 | H3: 46143.772 | I3: KH0056 | J3: Cửa hàng | K3: COD | L3: Miền Nam | M3: TP. Hồ Chí Minh | N3: =IFERROR(VLOOKUP(I3,Customers!$B$2:$L$81,11,FALSE),"") -> EMP008 | O3: =SUMIF(OderItems!$A$2:$A$510,A3,OderItems!$L$2:$L$510) -> 2806000 | P3: =SUMIF(OderItems!$A$2:$A$510,A3,OderItems!$G$2:$G$510) -> 45000 | Q3: =SUMIF(OderItems!$A$2:$A$510,A3,OderItems!$K$2:$K$510) -> 0 | R3: =O3+P3-Q3 -> 2851000 | S3: VNĐ | T3: =AND(C3="delivered",I3<>"",R3>0) -> TRUE
A4: DH00003 | B4: CUS00026 | C4: delivered | D4: 45805.419 | E4: 45805.503 | F4: 45807.419 | G4: 45811.419 | H4: 45813.419 | I4: KH0026 | J4: Ứng dụng | K4: Ví điện tử | L4: Miền Trung | M4: Bình Định | N4: =IFERROR(VLOOKUP(I4,Customers!$B$2:$L$81,11,FALSE),"") -> EMP002 | O4: =SUMIF(OderItems!$A$2:$A$510,A4,OderItems!$L$2:$L$510) -> 618000 | P4: =SUMIF(OderItems!$A$2:$A$510,A4,OderItems!$G$2:$G$510) -> 12000 | Q4: =SUMIF(OderItems!$A$2:$A$510,A4,OderItems!$K$2:$K$510) -> 0 | R4: =O4+P4-Q4 -> 630000 | S4: VNĐ | T4: =AND(C4="delivered",I4<>"",R4>0) -> TRUE
A5: DH00004 | B5: CUS00033 | C5: delivered | D5: 46121.639 | E5: 46121.722 | F5: 46123.639 | G5: 46127.639 | H5: 46129.639 | I5: KH0033 | J5: Website | K5: Thẻ ngân hàng | L5: Miền Bắc | M5: Bắc Ninh | N5: =IFERROR(VLOOKUP(I5,Customers!$B$2:$L$81,11,FALSE),"") -> EMP001 | O5: =SUMIF(OderItems!$A$2:$A$510,A5,OderItems!$L$2:$L$510) -> 1155000 | P5: =SUMIF(OderItems!$A$2:$A$510,A5,OderItems!$G$2:$G$510) -> 30000 | Q5: =SUMIF(OderItems!$A$2:$A$510,A5,OderItems!$K$2:$K$510) -> 0 | R5: =O5+P5-Q5 -> 1185000 | S5: VNĐ | T5: =AND(C5="delivered",I5<>"",R5>0) -> TRUE
A6: DH00005 | B6: CUS00078 | C6: delivered | D6: 46196.926 | E6: 46197.009 | F6: 46198.926 | G6: 46202.926 | H6: 46204.926 | I6: KH0078 | J6: Sàn thương mại điện tử | K6: COD | L6: Miền Trung | M6: Thừa Thiên Huế | N6: =IFERROR(VLOOKUP(I6,Customers!$B$2:$L$81,11,FALSE),"") -> EMP006 | O6: =SUMIF(OderItems!$A$2:$A$510,A6,OderItems!$L$2:$L$510) -> 2012000 | P6: =SUMIF(OderItems!$A$2:$A$510,A6,OderItems!$G$2:$G$510) -> 25000 | Q6: =SUMIF(OderItems!$A$2:$A$510,A6,OderItems!$K$2:$K$510) -> 0 | R6: =O6+P6-Q6 -> 2037000 | S6: VNĐ | T6: =AND(C6="delivered",I6<>"",R6>0) -> TRUE
A7: DH00006 | B7: CUS00053 | C7: delivered | D7: 45789.558 | E7: 45789.641 | F7: 45791.558 | G7: 45795.558 | H7: 45797.558 | I7: KH0053 | J7: Website | K7: Ví điện tử | L7: Miền Trung | M7: Thừa Thiên Huế | N7: =IFERROR(VLOOKUP(I7,Customers!$B$2:$L$81,11,FALSE),"") -> EMP005 | O7: =SUMIF(OderItems!$A$2:$A$510,A7,OderItems!$L$2:$L$510) -> 997000 | P7: =SUMIF(OderItems!$A$2:$A$510,A7,OderItems!$G$2:$G$510) -> 30000 | Q7: =SUMIF(OderItems!$A$2:$A$510,A7,OderItems!$K$2:$K$510) -> 0 | R7: =O7+P7-Q7 -> 1027000 | S7: VNĐ | T7: =AND(C7="delivered",I7<>"",R7>0) -> TRUE
A8: DH00007 | B8: CUS00041 | C8: delivered | D8: 45812.221 | E8: 45812.304 | F8: 45814.221 | G8: 45818.221 | H8: 45820.221 | I8: KH0041 | J8: Sàn thương mại điện tử | K8: Ví điện tử | L8: Miền Nam | M8: TP. Hồ Chí Minh | N8: =IFERROR(VLOOKUP(I8,Customers!$B$2:$L$81,11,FALSE),"") -> EMP001 | O8: =SUMIF(OderItems!$A$2:$A$510,A8,OderItems!$L$2:$L$510) -> 711000 | P8: =SUMIF(OderItems!$A$2:$A$510,A8,OderItems!$G$2:$G$510) -> 36000 | Q8: =SUMIF(OderItems!$A$2:$A$510,A8,OderItems!$K$2:$K$510) -> 0 | R8: =O8+P8-Q8 -> 747000 | S8: VNĐ | T8: =AND(C8="delivered",I8<>"",R8>0) -> TRUE
A9: DH00008 | B9: CUS00020 | C9: delivered | D9: 45522.834 | E9: 45522.917 | F9: 45524.834 | G9: 45528.834 | H9: 45530.834 | I9: KH0020 | J9: Website | K9: Ví điện tử | L9: Miền Nam | M9: Bà Rịa - Vũng Tàu | N9: =IFERROR(VLOOKUP(I9,Customers!$B$2:$L$81,11,FALSE),"") -> EMP004 | O9: =SUMIF(OderItems!$A$2:$A$510,A9,OderItems!$L$2:$L$510) -> 1905000 | P9: =SUMIF(OderItems!$A$2:$A$510,A9,OderItems!$G$2:$G$510) -> 42000 | Q9: =SUMIF(OderItems!$A$2:$A$510,A9,OderItems!$K$2:$K$510) -> 0 | R9: =O9+P9-Q9 -> 1947000 | S9: VNĐ | T9: =AND(C9="delivered",I9<>"",R9>0) -> TRUE
A10: DH00009 | B10: CUS00035 | C10: canceled | D10: 45335.874 | H10: 45343.874 | I10: KH0035 | J10: Cửa hàng | K10: Ví điện tử | L10: Miền Nam | M10: Bình Dương | N10: =IFERROR(VLOOKUP(I10,Customers!$B$2:$L$81,11,FALSE),"") -> EMP003 | O10: =SUMIF(OderItems!$A$2:$A$510,A10,OderItems!$L$2:$L$510) -> 1184000 | P10: =SUMIF(OderItems!$A$2:$A$510,A10,OderItems!$G$2:$G$510) -> 50000 | Q10: =SUMIF(OderItems!$A$2:$A$510,A10,OderItems!$K$2:$K$510) -> 0 | R10: =O10+P10-Q10 -> 1234000 | S10: VNĐ | T10: =AND(C10="delivered",I10<>"",R10>0) -> FALSE
A11: DH00010 | B11: CUS00036 | C11: delivered | D11: 45351.111 | E11: 45351.194 | F11: 45353.111 | G11: 45357.111 | H11: 45359.111 | I11: KH0036 | J11: Website | K11: Chuyển khoản | L11: Miền Trung | M11: Quảng Nam | N11: =IFERROR(VLOOKUP(I11,Customers!$B$2:$L$81,11,FALSE),"") -> EMP004 | O11: =SUMIF(OderItems!$A$2:$A$510,A11,OderItems!$L$2:$L$510) -> 198000 | P11: =SUMIF(OderItems!$A$2:$A$510,A11,OderItems!$G$2:$G$510) -> 12000 | Q11: =SUMIF(OderItems!$A$2:$A$510,A11,OderItems!$K$2:$K$510) -> 0 | R11: =O11+P11-Q11 -> 210000 | S11: VNĐ | T11: =AND(C11="delivered",I11<>"",R11>0) -> TRUE
A12: DH00011 | B12: CUS00022 | C12: delivered | D12: 45784.633 | E12: 45784.717 | F12: 45786.633 | G12: 45790.633 | H12: 45792.633 | I12: KH0022 | J12: Cửa hàng | K12: Chuyển khoản | L12: Miền Nam | M12: Đồng Nai | N12: =IFERROR(VLOOKUP(I12,Customers!$B$2:$L$81,11,FALSE),"") -> EMP006 | O12: =SUMIF(OderItems!$A$2:$A$510,A12,OderItems!$L$2:$L$510) -> 742000 | P12: =SUMIF(OderItems!$A$2:$A$510,A12,OderItems!$G$2:$G$510) -> 9000 | Q12: =SUMIF(OderItems!$A$2:$A$510,A12,OderItems!$K$2:$K$510) -> 0 | R12: =O12+P12-Q12 -> 751000 | S12: VNĐ | T12: =AND(C12="delivered",I12<>"",R12>0) -> TRUE
A13: DH00012 | B13: CUS00046 | C13: delivered | D13: 45376.16 | E13: 45376.244 | F13: 45378.16 | G13: 45382.16 | H13: 45384.16 | I13: KH0046 | J13: Ứng dụng | K13: Chuyển khoản | L13: Miền Nam | M13: Bà Rịa - Vũng Tàu | N13: =IFERROR(VLOOKUP(I13,Customers!$B$2:$L$81,11,FALSE),"") -> EMP006 | O13: =SUMIF(OderItems!$A$2:$A$510,A13,OderItems!$L$2:$L$510) -> 1841000 | P13: =SUMIF(OderItems!$A$2:$A$510,A13,OderItems!$G$2:$G$510) -> 27000 | Q13: =SUMIF(OderItems!$A$2:$A$510,A13,OderItems!$K$2:$K$510) -> 0 | R13: =O13+P13-Q13 -> 1868000 | S13: VNĐ | T13: =AND(C13="delivered",I13<>"",R13>0) -> TRUE
A14: DH00013 | B14: CUS00060 | C14: canceled | D14: 45614.794 | H14: 45622.794 | I14: KH0060 | J14: Cửa hàng | K14: Chuyển khoản | L14: Miền Bắc | M14: Thái Nguyên | N14: =IFERROR(VLOOKUP(I14,Customers!$B$2:$L$81,11,FALSE),"") -> EMP004 | O14: =SUMIF(OderItems!$A$2:$A$510,A14,OderItems!$L$2:$L$510) -> 1441000 | P14: =SUMIF(OderItems!$A$2:$A$510,A14,OderItems!$G$2:$G$510) -> 18000 | Q14: =SUMIF(OderItems!$A$2:$A$510,A14,OderItems!$K$2:$K$510) -> 0 | R14: =O14+P14-Q14 -> 1459000 | S14: VNĐ | T14: =AND(C14="delivered",I14<>"",R14>0) -> FALSE
A15: DH00014 | B15: CUS00006 | C15: delivered | D15: 45750.179 | E15: 45750.262 | F15: 45752.179 | G15: 45756.179 | H15: 45758.179 | I15: KH0006 | J15: Ứng dụng | K15: Chuyển khoản | L15: Miền Bắc | M15: Thái Nguyên | N15: =IFERROR(VLOOKUP(I15,Customers!$B$2:$L$81,11,FALSE),"") -> EMP006 | O15: =SUMIF(OderItems!$A$2:$A$510,A15,OderItems!$L$2:$L$510) -> 270000 | P15: =SUMIF(OderItems!$A$2:$A$510,A15,OderItems!$G$2:$G$510) -> 8000 | Q15: =SUMIF(OderItems!$A$2:$A$510,A15,OderItems!$K$2:$K$510) -> 0 | R15: =O15+P15-Q15 -> 278000 | S15: VNĐ | T15: =AND(C15="delivered",I15<>"",R15>0) -> TRUE
A16: DH00015 | B16: CUS00045 | C16: delivered | D16: 45785.099 | E16: 45785.182 | F16: 45787.099 | G16: 45791.099 | H16: 45793.099 | I16: KH0045 | J16: Cửa hàng | K16: Ví điện tử | L16: Miền Bắc | M16: Thái Nguyên | N16: =IFERROR(VLOOKUP(I16,Customers!$B$2:$L$81,11,FALSE),"") -> EMP005 | O16: =SUMIF(OderItems!$A$2:$A$510,A16,OderItems!$L$2:$L$510) -> 1186000 | P16: =SUMIF(OderItems!$A$2:$A$510,A16,OderItems!$G$2:$G$510) -> 25000 | Q16: =SUMIF(OderItems!$A$2:$A$510,A16,OderItems!$K$2:$K$510) -> 0 | R16: =O16+P16-Q16 -> 1211000 | S16: VNĐ | T16: =AND(C16="delivered",I16<>"",R16>0) -> TRUE
A17: DH00016 | B17: CUS00022 | C17: delivered | D17: 45315.592 | E17: 45315.676 | F17: 45317.592 | G17: 45321.592 | H17: 45323.592 | I17: KH0022 | J17: Ứng dụng | K17: Thẻ ngân hàng | L17: Miền Nam | M17: Đồng Nai | N17: =IFERROR(VLOOKUP(I17,Customers!$B$2:$L$81,11,FALSE),"") -> EMP006 | O17: =SUMIF(OderItems!$A$2:$A$510,A17,OderItems!$L$2:$L$510) -> 2404000 | P17: =SUMIF(OderItems!$A$2:$A$510,A17,OderItems!$G$2:$G$510) -> 57000 | Q17: =SUMIF(OderItems!$A$2:$A$510,A17,OderItems!$K$2:$K$510) -> 0 | R17: =O17+P17-Q17 -> 2461000 | S17: VNĐ | T17: =AND(C17="delivered",I17<>"",R17>0) -> TRUE
A18: DH00017 | B18: CUS00021 | C18: processing | D18: 46128.979 | E18: 46129.063 | H18: 46136.979 | I18: KH0021 | J18: Website | K18: Thẻ ngân hàng | L18: Miền Nam | M18: Cần Thơ | N18: =IFERROR(VLOOKUP(I18,Customers!$B$2:$L$81,11,FALSE),"") -> EMP005 | O18: =SUMIF(OderItems!$A$2:$A$510,A18,OderItems!$L$2:$L$510) -> 3528000 | P18: =SUMIF(OderItems!$A$2:$A$510,A18,OderItems!$G$2:$G$510) -> 31000 | Q18: =SUMIF(OderItems!$A$2:$A$510,A18,OderItems!$K$2:$K$510) -> 0 | R18: =O18+P18-Q18 -> 3559000 | S18: VNĐ | T18: =AND(C18="delivered",I18<>"",R18>0) -> FALSE
A19: DH00018 | B19: CUS00033 | C19: returned | D19: 45396.033 | E19: 45396.117 | F19: 45398.033 | G19: 45402.033 | H19: 45404.033 | I19: KH0033 | J19: Website | K19: COD | L19: Miền Bắc | M19: Bắc Ninh | N19: =IFERROR(VLOOKUP(I19,Customers!$B$2:$L$81,11,FALSE),"") -> EMP001 | O19: =SUMIF(OderItems!$A$2:$A$510,A19,OderItems!$L$2:$L$510) -> 1075000 | P19: =SUMIF(OderItems!$A$2:$A$510,A19,OderItems!$G$2:$G$510) -> 19000 | Q19: =SUMIF(OderItems!$A$2:$A$510,A19,OderItems!$K$2:$K$510) -> 0 | R19: =O19+P19-Q19 -> 1094000 | S19: VNĐ | T19: =AND(C19="delivered",I19<>"",R19>0) -> FALSE
A20: DH00019 | B20: CUS00021 | C20: canceled | D20: 45767.12 | H20: 45775.12 | I20: KH0021 | J20: Cửa hàng | K20: Ví điện tử | L20: Miền Nam | M20: Cần Thơ | N20: =IFERROR(VLOOKUP(I20,Customers!$B$2:$L$81,11,FALSE),"") -> EMP005 | O20: =SUMIF(OderItems!$A$2:$A$510,A20,OderItems!$L$2:$L$510) -> 1439000 | P20: =SUMIF(OderItems!$A$2:$A$510,A20,OderItems!$G$2:$G$510) -> 38000 | Q20: =SUMIF(OderItems!$A$2:$A$510,A20,OderItems!$K$2:$K$510) -> 0 | R20: =O20+P20-Q20 -> 1477000 | S20: VNĐ | T20: =AND(C20="delivered",I20<>"",R20>0) -> FALSE
A21: DH00020 | B21: CUS00017 | C21: delivered | D21: 45784.588 | E21: 45784.672 | F21: 45786.588 | G21: 45790.588 | H21: 45792.588 | I21: KH0017 | J21: Sàn thương mại điện tử | K21: Thẻ ngân hàng | L21: Miền Nam | M21: Bà Rịa - Vũng Tàu | N21: =IFERROR(VLOOKUP(I21,Customers!$B$2:$L$81,11,FALSE),"") -> EMP001 | O21: =SUMIF(OderItems!$A$2:$A$510,A21,OderItems!$L$2:$L$510) -> 770000 | P21: =SUMIF(OderItems!$A$2:$A$510,A21,OderItems!$G$2:$G$510) -> 17000 | Q21: =SUMIF(OderItems!$A$2:$A$510,A21,OderItems!$K$2:$K$510) -> 0 | R21: =O21+P21-Q21 -> 787000 | S21: VNĐ | T21: =AND(C21="delivered",I21<>"",R21>0) -> TRUE
A22: DH00021 | B22: CUS00060 | C22: delivered | D22: 46190.641 | E22: 46190.724 | F22: 46192.641 | G22: 46196.641 | H22: 46198.641 | I22: KH0060 | J22: Cửa hàng | K22: Ví điện tử | L22: Miền Bắc | M22: Thái Nguyên | N22: =IFERROR(VLOOKUP(I22,Customers!$B$2:$L$81,11,FALSE),"") -> EMP004 | O22: =SUMIF(OderItems!$A$2:$A$510,A22,OderItems!$L$2:$L$510) -> 580000 | P22: =SUMIF(OderItems!$A$2:$A$510,A22,OderItems!$G$2:$G$510) -> 12000 | Q22: =SUMIF(OderItems!$A$2:$A$510,A22,OderItems!$K$2:$K$510) -> 0 | R22: =O22+P22-Q22 -> 592000 | S22: VNĐ | T22: =AND(C22="delivered",I22<>"",R22>0) -> TRUE
A23: DH00022 | B23: CUS00050 | C23: delivered | D23: 45767.053 | E23: 45767.136 | F23: 45769.053 | G23: 45773.053 | H23: 45775.053 | I23: KH0050 | J23: Sàn thương mại điện tử | K23: Thẻ ngân hàng | L23: Miền Nam | M23: Cần Thơ | N23: =IFERROR(VLOOKUP(I23,Customers!$B$2:$L$81,11,FALSE),"") -> EMP002 | O23: =SUMIF(OderItems!$A$2:$A$510,A23,OderItems!$L$2:$L$510) -> 500000 | P23: =SUMIF(OderItems!$A$2:$A$510,A23,OderItems!$G$2:$G$510) -> 13000 | Q23: =SUMIF(OderItems!$A$2:$A$510,A23,OderItems!$K$2:$K$510) -> 0 | R23: =O23+P23-Q23 -> 513000 | S23: VNĐ | T23: =AND(C23="delivered",I23<>"",R23>0) -> TRUE
A24: DH00023 | B24: CUS00013 | C24: delivered | D24: 45794.691 | E24: 45794.775 | F24: 45796.691 | G24: 45800.691 | H24: 45802.691 | I24: KH0013 | J24: Sàn thương mại điện tử | K24: Chuyển khoản | L24: Miền Trung | M24: Đà Nẵng | N24: =IFERROR(VLOOKUP(I24,Customers!$B$2:$L$81,11,FALSE),"") -> EMP005 | O24: =SUMIF(OderItems!$A$2:$A$510,A24,OderItems!$L$2:$L$510) -> 3849000 | P24: =SUMIF(OderItems!$A$2:$A$510,A24,OderItems!$G$2:$G$510) -> 76000 | Q24: =SUMIF(OderItems!$A$2:$A$510,A24,OderItems!$K$2:$K$510) -> 0 | R24: =O24+P24-Q24 -> 3925000 | S24: VNĐ | T24: =AND(C24="delivered",I24<>"",R24>0) -> TRUE
A25: DH00024 | B25: CUS00032 | C25: canceled | D25: 46062.116 | H25: 46070.116 | I25: KH0032 | J25: Website | K25: Thẻ ngân hàng | L25: Miền Nam | M25: Bà Rịa - Vũng Tàu | N25: =IFERROR(VLOOKUP(I25,Customers!$B$2:$L$81,11,FALSE),"") -> EMP008 | O25: =SUMIF(OderItems!$A$2:$A$510,A25,OderItems!$L$2:$L$510) -> 1911000 | P25: =SUMIF(OderItems!$A$2:$A$510,A25,OderItems!$G$2:$G$510) -> 33000 | Q25: =SUMIF(OderItems!$A$2:$A$510,A25,OderItems!$K$2:$K$510) -> 0 | R25: =O25+P25-Q25 -> 1944000 | S25: VNĐ | T25: =AND(C25="delivered",I25<>"",R25>0) -> FALSE
A26: DH00025 | B26: CUS00017 | C26: delivered | D26: 45408.55 | E26: 45408.633 | F26: 45410.55 | G26: 45414.55 | H26: 45416.55 | I26: KH0017 | J26: Sàn thương mại điện tử | K26: COD | L26: Miền Nam | M26: Bà Rịa - Vũng Tàu | N26: =IFERROR(VLOOKUP(I26,Customers!$B$2:$L$81,11,FALSE),"") -> EMP001 | O26: =SUMIF(OderItems!$A$2:$A$510,A26,OderItems!$L$2:$L$510) -> 2710000 | P26: =SUMIF(OderItems!$A$2:$A$510,A26,OderItems!$G$2:$G$510) -> 47000 | Q26: =SUMIF(OderItems!$A$2:$A$510,A26,OderItems!$K$2:$K$510) -> 0 | R26: =O26+P26-Q26 -> 2757000 | S26: VNĐ | T26: =AND(C26="delivered",I26<>"",R26>0) -> TRUE
A27: DH00026 | B27: CUS00003 | C27: returned | D27: 45468.779 | E27: 45468.863 | F27: 45470.779 | G27: 45474.779 | H27: 45476.779 | I27: KH0003 | J27: Ứng dụng | K27: Thẻ ngân hàng | L27: Miền Trung | M27: Quảng Nam | N27: =IFERROR(VLOOKUP(I27,Customers!$B$2:$L$81,11,FALSE),"") -> EMP003 | O27: =SUMIF(OderItems!$A$2:$A$510,A27,OderItems!$L$2:$L$510) -> 1463000 | P27: =SUMIF(OderItems!$A$2:$A$510,A27,OderItems!$G$2:$G$510) -> 33000 | Q27: =SUMIF(OderItems!$A$2:$A$510,A27,OderItems!$K$2:$K$510) -> 0 | R27: =O27+P27-Q27 -> 1496000 | S27: VNĐ | T27: =AND(C27="delivered",I27<>"",R27>0) -> FALSE
A28: DH00027 | B28: CUS00047 | C28: delivered | D28: 46222.939 | E28: 46223.022 | F28: 46224.939 | G28: 46228.939 | H28: 46230.939 | I28: KH0047 | J28: Sàn thương mại điện tử | K28: COD | L28: Miền Bắc | M28: Hải Phòng | N28: =IFERROR(VLOOKUP(I28,Customers!$B$2:$L$81,11,FALSE),"") -> EMP007 | O28: =SUMIF(OderItems!$A$2:$A$510,A28,OderItems!$L$2:$L$510) -> 2329000 | P28: =SUMIF(OderItems!$A$2:$A$510,A28,OderItems!$G$2:$G$510) -> 48000 | Q28: =SUMIF(OderItems!$A$2:$A$510,A28,OderItems!$K$2:$K$510) -> 0 | R28: =O28+P28-Q28 -> 2377000 | S28: VNĐ | T28: =AND(C28="delivered",I28<>"",R28>0) -> TRUE
A29: DH00028 | B29: CUS00043 | C29: delivered | D29: 46098.255 | E29: 46098.338 | F29: 46100.255 | G29: 46104.255 | H29: 46106.255 | I29: KH0043 | J29: Ứng dụng | K29: Thẻ ngân hàng | L29: Miền Nam | M29: TP. Hồ Chí Minh | N29: =IFERROR(VLOOKUP(I29,Customers!$B$2:$L$81,11,FALSE),"") -> EMP003 | O29: =SUMIF(OderItems!$A$2:$A$510,A29,OderItems!$L$2:$L$510) -> 4420000 | P29: =SUMIF(OderItems!$A$2:$A$510,A29,OderItems!$G$2:$G$510) -> 61000 | Q29: =SUMIF(OderItems!$A$2:$A$510,A29,OderItems!$K$2:$K$510) -> 0 | R29: =O29+P29-Q29 -> 4481000 | S29: VNĐ | T29: =AND(C29="delivered",I29<>"",R29>0) -> TRUE
A30: DH00029 | B30: CUS00001 | C30: delivered | D30: 45617.08 | E30: 45617.164 | F30: 45619.08 | G30: 45623.08 | H30: 45625.08 | I30: KH0001 | J30: Cửa hàng | K30: COD | L30: Miền Trung | M30: Đà Nẵng | N30: =IFERROR(VLOOKUP(I30,Customers!$B$2:$L$81,11,FALSE),"") -> EMP001 | O30: =SUMIF(OderItems!$A$2:$A$510,A30,OderItems!$L$2:$L$510) -> 2250000 | P30: =SUMIF(OderItems!$A$2:$A$510,A30,OderItems!$G$2:$G$510) -> 32000 | Q30: =SUMIF(OderItems!$A$2:$A$510,A30,OderItems!$K$2:$K$510) -> 0 | R30: =O30+P30-Q30 -> 2282000 | S30: VNĐ | T30: =AND(C30="delivered",I30<>"",R30>0) -> TRUE
A31: DH00030 | B31: CUS00006 | C31: returned | D31: 45400.139 | E31: 45400.222 | F31: 45402.139 | G31: 45406.139 | H31: 45408.139 | I31: KH0006 | J31: Cửa hàng | K31: COD | L31: Miền Bắc | M31: Thái Nguyên | N31: =IFERROR(VLOOKUP(I31,Customers!$B$2:$L$81,11,FALSE),"") -> EMP006 | O31: =SUMIF(OderItems!$A$2:$A$510,A31,OderItems!$L$2:$L$510) -> 930000 | P31: =SUMIF(OderItems!$A$2:$A$510,A31,OderItems!$G$2:$G$510) -> 13000 | Q31: =SUMIF(OderItems!$A$2:$A$510,A31,OderItems!$K$2:$K$510) -> 0 | R31: =O31+P31-Q31 -> 943000 | S31: VNĐ | T31: =AND(C31="delivered",I31<>"",R31>0) -> FALSE
A32: DH00031 | B32: CUS00027 | C32: delivered | D32: 45412.909 | E32: 45412.992 | F32: 45414.909 | G32: 45418.909 | H32: 45420.909 | I32: KH0027 | J32: Sàn thương mại điện tử | K32: Thẻ ngân hàng | L32: Miền Nam | M32: Đồng Nai | N32: =IFERROR(VLOOKUP(I32,Customers!$B$2:$L$81,11,FALSE),"") -> EMP003 | O32: =SUMIF(OderItems!$A$2:$A$510,A32,OderItems!$L$2:$L$510) -> 2968000 | P32: =SUMIF(OderItems!$A$2:$A$510,A32,OderItems!$G$2:$G$510) -> 33000 | Q32: =SUMIF(OderItems!$A$2:$A$510,A32,OderItems!$K$2:$K$510) -> 0 | R32: =O32+P32-Q32 -> 3001000 | S32: VNĐ | T32: =AND(C32="delivered",I32<>"",R32>0) -> TRUE
A33: DH00032 | B33: CUS00056 | C33: delivered | D33: 45384.211 | E33: 45384.294 | F33: 45386.211 | G33: 45390.211 | H33: 45392.211 | I33: KH0056 | J33: Ứng dụng | K33: COD | L33: Miền Nam | M33: TP. Hồ Chí Minh | N33: =IFERROR(VLOOKUP(I33,Customers!$B$2:$L$81,11,FALSE),"") -> EMP008 | O33: =SUMIF(OderItems!$A$2:$A$510,A33,OderItems!$L$2:$L$510) -> 2661000 | P33: =SUMIF(OderItems!$A$2:$A$510,A33,OderItems!$G$2:$G$510) -> 44000 | Q33: =SUMIF(OderItems!$A$2:$A$510,A33,OderItems!$K$2:$K$510) -> 0 | R33: =O33+P33-Q33 -> 2705000 | S33: VNĐ | T33: =AND(C33="delivered",I33<>"",R33>0) -> TRUE
A34: DH00033 | B34: CUS00054 | C34: processing | D34: 46191.523 | E34: 46191.606 | H34: 46199.523 | I34: KH0054 | J34: Ứng dụng | K34: COD | L34: Miền Nam | M34: Cần Thơ | N34: =IFERROR(VLOOKUP(I34,Customers!$B$2:$L$81,11,FALSE),"") -> EMP006 | O34: =SUMIF(OderItems!$A$2:$A$510,A34,OderItems!$L$2:$L$510) -> 1430000 | P34: =SUMIF(OderItems!$A$2:$A$510,A34,OderItems!$G$2:$G$510) -> 20000 | Q34: =SUMIF(OderItems!$A$2:$A$510,A34,OderItems!$K$2:$K$510) -> 0 | R34: =O34+P34-Q34 -> 1450000 | S34: VNĐ | T34: =AND(C34="delivered",I34<>"",R34>0) -> FALSE
A35: DH00034 | B35: CUS00046 | C35: delivered | D35: 45988.34 | E35: 45988.423 | F35: 45990.34 | G35: 45994.34 | H35: 45996.34 | I35: KH0046 | J35: Ứng dụng | K35: Thẻ ngân hàng | L35: Miền Nam | M35: Bà Rịa - Vũng Tàu | N35: =IFERROR(VLOOKUP(I35,Customers!$B$2:$L$81,11,FALSE),"") -> EMP006 | O35: =SUMIF(OderItems!$A$2:$A$510,A35,OderItems!$L$2:$L$510) -> 1692000 | P35: =SUMIF(OderItems!$A$2:$A$510,A35,OderItems!$G$2:$G$510) -> 32000 | Q35: =SUMIF(OderItems!$A$2:$A$510,A35,OderItems!$K$2:$K$510) -> 0 | R35: =O35+P35-Q35 -> 1724000 | S35: VNĐ | T35: =AND(C35="delivered",I35<>"",R35>0) -> TRUE
A36: DH00035 | B36: CUS00010 | C36: delivered | D36: 45723.27 | E36: 45723.353 | F36: 45725.27 | G36: 45729.27 | H36: 45731.27 | I36: KH0010 | J36: Website | K36: Ví điện tử | L36: Miền Nam | M36: Bà Rịa - Vũng Tàu | N36: =IFERROR(VLOOKUP(I36,Customers!$B$2:$L$81,11,FALSE),"") -> EMP002 | O36: =SUMIF(OderItems!$A$2:$A$510,A36,OderItems!$L$2:$L$510) -> 1350000 | P36: =SUMIF(OderItems!$A$2:$A$510,A36,OderItems!$G$2:$G$510) -> 27000 | Q36: =SUMIF(OderItems!$A$2:$A$510,A36,OderItems!$K$2:$K$510) -> 0 | R36: =O36+P36-Q36 -> 1377000 | S36: VNĐ | T36: =AND(C36="delivered",I36<>"",R36>0) -> TRUE
A37: DH00036 | B37: CUS00015 | C37: canceled | D37: 45519.575 | H37: 45527.575 | I37: KH0015 | J37: Sàn thương mại điện tử | K37: Ví điện tử | L37: Miền Nam | M37: Long An | N37: =IFERROR(VLOOKUP(I37,Customers!$B$2:$L$81,11,FALSE),"") -> EMP007 | O37: =SUMIF(OderItems!$A$2:$A$510,A37,OderItems!$L$2:$L$510) -> 752000 | P37: =SUMIF(OderItems!$A$2:$A$510,A37,OderItems!$G$2:$G$510) -> 20000 | Q37: =SUMIF(OderItems!$A$2:$A$510,A37,OderItems!$K$2:$K$510) -> 0 | R37: =O37+P37-Q37 -> 772000 | S37: VNĐ | T37: =AND(C37="delivered",I37<>"",R37>0) -> FALSE
A38: DH00037 | B38: CUS00018 | C38: processing | D38: 45419.828 | E38: 45419.911 | H38: 45427.828 | I38: KH0018 | J38: Website | K38: Thẻ ngân hàng | L38: Miền Nam | M38: Long An | N38: =IFERROR(VLOOKUP(I38,Customers!$B$2:$L$81,11,FALSE),"") -> EMP002 | O38: =SUMIF(OderItems!$A$2:$A$510,A38,OderItems!$L$2:$L$510) -> 2056000 | P38: =SUMIF(OderItems!$A$2:$A$510,A38,OderItems!$G$2:$G$510) -> 29000 | Q38: =SUMIF(OderItems!$A$2:$A$510,A38,OderItems!$K$2:$K$510) -> 0 | R38: =O38+P38-Q38 -> 2085000 | S38: VNĐ | T38: =AND(C38="delivered",I38<>"",R38>0) -> FALSE
A39: DH00038 | B39: CUS00052 | C39: delivered | D39: 45918.197 | E39: 45918.28 | F39: 45920.197 | G39: 45924.197 | H39: 45926.197 | I39: KH0052 | J39: Website | K39: COD | L39: Miền Nam | M39: Bà Rịa - Vũng Tàu | N39: =IFERROR(VLOOKUP(I39,Customers!$B$2:$L$81,11,FALSE),"") -> EMP004 | O39: =SUMIF(OderItems!$A$2:$A$510,A39,OderItems!$L$2:$L$510) -> 1092000 | P39: =SUMIF(OderItems!$A$2:$A$510,A39,OderItems!$G$2:$G$510) -> 17000 | Q39: =SUMIF(OderItems!$A$2:$A$510,A39,OderItems!$K$2:$K$510) -> 0 | R39: =O39+P39-Q39 -> 1109000 | S39: VNĐ | T39: =AND(C39="delivered",I39<>"",R39>0) -> TRUE
A40: DH00039 | B40: CUS00040 | C40: processing | D40: 45768.864 | E40: 45768.947 | H40: 45776.864 | I40: KH0040 | J40: Ứng dụng | K40: Thẻ ngân hàng | L40: Miền Trung | M40: Đà Nẵng | N40: =IFERROR(VLOOKUP(I40,Customers!$B$2:$L$81,11,FALSE),"") -> EMP008 | O40: =SUMIF(OderItems!$A$2:$A$510,A40,OderItems!$L$2:$L$510) -> 1419000 | P40: =SUMIF(OderItems!$A$2:$A$510,A40,OderItems!$G$2:$G$510) -> 56000 | Q40: =SUMIF(OderItems!$A$2:$A$510,A40,OderItems!$K$2:$K$510) -> 0 | R40: =O40+P40-Q40 -> 1475000 | S40: VNĐ | T40: =AND(C40="delivered",I40<>"",R40>0) -> FALSE
...

Sheet OderItems
A1: order_id | B1: order_item_id | C1: product_id | D1: seller_id | E1: shipping_limit_date | F1: price | G1: freight_value | H1: Quantity | I1: LineAmount | J1: OrderDetailID | K1: discount_value | L1: line_subtotal | M1: line_total
A2: DH00001 | B2: 1 | C2: SP019 | D2: NCC0019 | E2: 45906.813 | F2: 420000 | G2: 13000 | H2: 2 | I2: 840000 | J2: CT000001 | K2: =0 -> 0 | L2: =F2*H2 -> 840000 | M2: =L2+G2-K2 -> 853000
A3: DH00001 | B3: 2 | C3: SP003 | D3: NCC0003 | E3: 45906.813 | F3: 390000 | G3: 16000 | H3: 4 | I3: 1560000 | J3: CT000002 | K3: =0 -> 0 | L3: =F3*H3 -> 1560000 | M3: =L3+G3-K3 -> 1576000
A4: DH00001 | B4: 3 | C4: SP039 | D4: NCC0009 | E4: 45906.813 | F4: 142000 | G4: 7000 | H4: 2 | I4: 284000 | J4: CT000003 | K4: =0 -> 0 | L4: =F4*H4 -> 284000 | M4: =L4+G4-K4 -> 291000
A5: DH00001 | B5: 4 | C5: SP029 | D5: NCC0029 | E5: 45906.813 | F5: 350000 | G5: 21000 | H5: 2 | I5: 700000 | J5: CT000004 | K5: =0 -> 0 | L5: =F5*H5 -> 700000 | M5: =L5+G5-K5 -> 721000
A6: DH00002 | B6: 1 | C6: SP029 | D6: NCC0029 | E6: 46137.272 | F6: 350000 | G6: 11000 | H6: 3 | I6: 1050000 | J6: CT000005 | K6: =0 -> 0 | L6: =F6*H6 -> 1050000 | M6: =L6+G6-K6 -> 1061000
A7: DH00002 | B7: 2 | C7: SP008 | D7: NCC0008 | E7: 46137.272 | F7: 266000 | G7: 11000 | H7: 3 | I7: 798000 | J7: CT000006 | K7: =0 -> 0 | L7: =F7*H7 -> 798000 | M7: =L7+G7-K7 -> 809000
A8: DH00002 | B8: 3 | C8: SP023 | D8: NCC0023 | E8: 46137.272 | F8: 126000 | G8: 6000 | H8: 3 | I8: 378000 | J8: CT000007 | K8: =0 -> 0 | L8: =F8*H8 -> 378000 | M8: =L8+G8-K8 -> 384000
A9: DH00002 | B9: 4 | C9: SP030 | D9: NCC0030 | E9: 46137.272 | F9: 290000 | G9: 17000 | H9: 2 | I9: 580000 | J9: CT000008 | K9: =0 -> 0 | L9: =F9*H9 -> 580000 | M9: =L9+G9-K9 -> 597000
A10: DH00003 | B10: 1 | C10: SP021 | D10: NCC0021 | E10: 45806.919 | F10: 89000 | G10: 3000 | H10: 2 | I10: 178000 | J10: CT000009 | K10: =0 -> 0 | L10: =F10*H10 -> 178000 | M10: =L10+G10-K10 -> 181000
A11: DH00003 | B11: 2 | C11: SP002 | D11: NCC0002 | E11: 45806.919 | F11: 220000 | G11: 9000 | H11: 2 | I11: 440000 | J11: CT000010 | K11: =0 -> 0 | L11: =F11*H11 -> 440000 | M11: =L11+G11-K11 -> 449000
A12: DH00004 | B12: 1 | C12: SP031 | D12: NCC0001 | E12: 46123.139 | F12: 189000 | G12: 9000 | H12: 4 | I12: 756000 | J12: CT000011 | K12: =0 -> 0 | L12: =F12*H12 -> 756000 | M12: =L12+G12-K12 -> 765000
A13: DH00004 | B13: 2 | C13: SP025 | D13: NCC0025 | E13: 46123.139 | F13: 280000 | G13: 17000 | H13: 1 | I13: 280000 | J13: CT000012 | K13: =0 -> 0 | L13: =F13*H13 -> 280000 | M13: =L13+G13-K13 -> 297000
... A510: DH00200 | B510: 4 | C510: SP033 | D510: NCC0003 | E510: 45530.487 | F510: 125000 | G510: 4000 | H510: 4 | I510: 500000 | J510: CT000509 | K510: =0 -> 0 | L510: =F510*H510 -> 500000 | M510: =L510+G510-K510 -> 504000

Sheet Payments
A1: order_id | B1: payment_sequential | C1: payment_type | D1: payment_installments | E1: payment_value | F1: PaymentMethodVN | G1: Currency
A2: DH00001 | B2: 1 | C2: bank_transfer | D2: 1 | E2: 3441000 | F2: Chuyển khoản | G2: VNĐ
A3: DH00002 | B3: 1 | C3: cash_on_delivery | D3: 1 | E3: 2851000 | F3: COD | G3: VNĐ
A4: DH00003 | B4: 1 | C4: e_wallet | D4: 1 | E4: 630000 | F4: Ví điện tử | G4: VNĐ
A5: DH00004 | B5: 1 | C5: credit_card | D5: 4 | E5: 1185000 | F5: Thẻ ngân hàng | G5: VNĐ
A6: DH00005 | B6: 1 | C6: cash_on_delivery | D6: 1 | E6: 2037000 | F6: COD | G6: VNĐ
A7: DH00006 | B7: 1 | C7: e_wallet | D7: 1 | E7: 1027000 | F7: Ví điện tử | G7: VNĐ
A8: DH00007 | B8: 1 | C8: e_wallet | D8: 1 | E8: 747000 | F8: Ví điện tử | G8: VNĐ
A9: DH00008 | B9: 1 | C9: e_wallet | D9: 1 | E9: 1947000 | F9: Ví điện tử | G9: VNĐ
A10: DH00009 | B10: 1 | C10: e_wallet | D10: 1 | E10: 1234000 | F10: Ví điện tử | G10: VNĐ
A11: DH00010 | B11: 1 | C11: bank_transfer | D11: 1 | E11: 210000 | F11: Chuyển khoản | G11: VNĐ
A12: DH00011 | B12: 1 | C12: bank_transfer | D12: 1 | E12: 751000 | F12: Chuyển khoản | G12: VNĐ
A13: DH00012 | B13: 1 | C13: bank_transfer | D13: 1 | E13: 1868000 | F13: Chuyển khoản | G13: VNĐ
... A201: DH00200 | B201: 1 | C201: e_wallet | D201: 1 | E201: 1952000 | F201: Ví điện tử | G201: VNĐ

Sheet Reviews
A1: review_id | B1: order_id | C1: review_score | D1: review_comment_title | E1: review_comment_message | F1: review_creation_date | G1: review_answer_timestamp | H1: CustomerID | I1: Channel
A2: TT00001 | B2: DH00001 | C2: 4 | D2: Hài lòng | E2: Sản phẩm đúng mô tả, đóng gói cẩn thận. | F2: 45908.313 | G2: 45908.563 | H2: KH0057 | I2: Website/App
A3: TT00002 | B3: DH00002 | C3: 5 | D3: Hài lòng | E3: Hài lòng với sản phẩm và dịch vụ. | F3: 46143.772 | G3: 46144.022 | H3: KH0056 | I3: Website/App
A4: TT00003 | B4: DH00003 | C4: 3 | D4: Bình thường | E4: Giao hàng nhanh, chất lượng tốt. | F4: 45816.419 | G4: 45816.669 | H4: KH0026 | I4: Website/App
A5: TT00004 | B5: DH00004 | C5: 3 | D5: Bình thường | E5: Giao hàng nhanh, chất lượng tốt. | F5: 46124.639 | G5: 46124.889 | H5: KH0033 | I5: Website/App
A6: TT00005 | B6: DH00005 | C6: 5 | D6: Hài lòng | E6: Sản phẩm đúng mô tả, đóng gói cẩn thận. | F6: 46207.926 | G6: 46208.176 | H6: KH0078 | I6: Website/App
A7: TT00006 | B7: DH00006 | C7: 4 | D7: Hài lòng | E7: Sẽ tiếp tục ủng hộ cửa hàng. | F7: 45801.558 | G7: 45801.808 | H7: KH0053 | I7: Website/App
A8: TT00007 | B8: DH00008 | C8: 5 | D8: Hài lòng | E8: Hài lòng với sản phẩm và dịch vụ. | F8: 45527.834 | G8: 45528.084 | H8: KH0020 | I8: Website/App
A9: TT00008 | B9: DH00010 | C9: 5 | D9: Hài lòng | E9: Sản phẩm đẹp, giá hợp lý. | F9: 45358.111 | G9: 45358.361 | H9: KH0036 | I9: Website/App
A10: TT00009 | B10: DH00011 | C10: 3 | D10: Bình thường | E10: Sản phẩm đẹp, giá hợp lý. | F10: 45795.633 | G10: 45795.883 | H10: KH0022 | I10: Website/App
A11: TT00010 | B11: DH00014 | C11: 5 | D11: Hài lòng | E11: Sản phẩm đúng mô tả, đóng gói cẩn thận. | F11: 45758.179 | G11: 45758.429 | H11: KH0006 | I11: Website/App
A12: TT00011 | B12: DH00015 | C12: 3 | D12: Bình thường | E12: Sản phẩm đúng mô tả, đóng gói cẩn thận. | F12: 45797.099 | G12: 45797.349 | H12: KH0045 | I12: Website/App
A13: TT00012 | B13: DH00016 | C13: 5 | D13: Hài lòng | E13: Sản phẩm đúng mô tả, đóng gói cẩn thận. | F13: 45329.592 | G13: 45329.842 | H13: KH0022 | I13: Website/App
... A142: TT00141 | B142: DH00200 | C142: 3 | D142: Bình thường | E142: Sản phẩm đúng mô tả, đóng gói cẩn thận. | F142: 45538.987 | G142: 45539.237 | H142: KH0032 | I142: Website/App

Sheet Sellers
A1: seller_id | B1: seller_zip_code_prefix | C1: seller_city | D1: seller_state | E1: Region | F1: SellerName
A2: NCC0001 | B2: 10000 | C2: Hà Nội | D2: HN | E2: Miền Bắc | F2: Nhà bán hàng 01
A3: NCC0002 | B3: 18000 | C3: Hải Phòng | D3: HP | E3: Miền Bắc | F3: Nhà bán hàng 02
A4: NCC0003 | B4: 20000 | C4: Quảng Ninh | D4: QN | E4: Miền Bắc | F4: Nhà bán hàng 03
A5: NCC0004 | B5: 16000 | C5: Bắc Ninh | D5: BN | E5: Miền Bắc | F5: Nhà bán hàng 04
A6: NCC0005 | B6: 17000 | C6: Nam Định | D6: ND | E6: Miền Bắc | F6: Nhà bán hàng 05
A7: NCC0006 | B7: 25000 | C7: Thái Nguyên | D7: TN | E7: Miền Bắc | F7: Nhà bán hàng 06
A8: NCC0007 | B8: 55000 | C8: Đà Nẵng | D8: DN | E8: Miền Trung | F8: Nhà bán hàng 07
A9: NCC0008 | B9: 53000 | C9: Thừa Thiên Huế | D9: TTH | E9: Miền Trung | F9: Nhà bán hàng 08
A10: NCC0009 | B10: 56000 | C10: Quảng Nam | D10: QNA | E10: Miền Trung | F10: Nhà bán hàng 09
A11: NCC0010 | B11: 65000 | C11: Khánh Hòa | D11: KH | E11: Miền Trung | F11: Nhà bán hàng 10
A12: NCC0011 | B12: 43000 | C12: Nghệ An | D12: NA | E12: Miền Trung | F12: Nhà bán hàng 11
A13: NCC0012 | B13: 59000 | C13: Bình Định | D13: BD | E13: Miền Trung | F13: Nhà bán hàng 12
... A31: NCC0030 | B31: 59000 | C31: Bình Định | D31: BD | E31: Miền Trung | F31: Nhà bán hàng 30

Sheet Geolocation
A1: geolocation_zip_code_prefix | B1: geolocation_lat | C1: geolocation_lng | D1: geolocation_city | E1: geolocation_state | F1: Region
A2: 10000 | B2: 21.0285 | C2: 105.8542 | D2: Hà Nội | E2: HN | F2: Miền Bắc
A3: 18000 | B3: 20.8449 | C3: 106.6881 | D3: Hải Phòng | E3: HP | F3: Miền Bắc
A4: 20000 | B4: 20.95 | C4: 107.08 | D4: Quảng Ninh | E4: QN | F4: Miền Bắc
A5: 16000 | B5: 21.1861 | C5: 106.0763 | D5: Bắc Ninh | E5: BN | F5: Miền Bắc
A6: 17000 | B6: 20.4388 | C6: 106.1621 | D6: Nam Định | E6: ND | F6: Miền Bắc
A7: 25000 | B7: 21.5942 | C7: 105.8482 | D7: Thái Nguyên | E7: TN | F7: Miền Bắc
A8: 55000 | B8: 16.0544 | C8: 108.2022 | D8: Đà Nẵng | E8: DN | F8: Miền Trung
A9: 53000 | B9: 16.4637 | C9: 107.5909 | D9: Thừa Thiên Huế | E9: TTH | F9: Miền Trung
A10: 56000 | B10: 15.5394 | C10: 108.0191 | D10: Quảng Nam | E10: QNA | F10: Miền Trung
A11: 65000 | B11: 12.2388 | C11: 109.1967 | D11: Khánh Hòa | E11: KH | F11: Miền Trung
A12: 43000 | B12: 18.6796 | C12: 105.6813 | D12: Nghệ An | E12: NA | F12: Miền Trung
A13: 59000 | B13: 13.782 | C13: 109.219 | D13: Bình Định | E13: BD | F13: Miền Trung
... A19: 78000 | B19: 10.4114 | C19: 107.1362 | D19: Bà Rịa - Vũng Tàu | E19: BRVT | F19: Miền Nam

Sheet DataDictionary
A1: SheetName | B1: FieldName | C1: BusinessName | D1: Description | E1: DataType | F1: LengthFormat | G1: Required | H1: KeyType | I1: ReferenceField | J1: AllowedValues | K1: ValidationRule | L1: NullHandling | M1: TransformationRule | N1: ExampleValue | O1: SourceType
A2: Customers | B2: customer_id | C2: customer_id | D2: Đặc tả trường customer_id của bảng Customers | E2: Text | F2: Text | G2: Yes | H2: PK | K2: Không trùng và không rỗng | L2: Reject | M2: Giữ nguyên/chuẩn hóa ETL | N2: customer_id | O2: Olist structure
A3: Customers | B3: customer_unique_id | C3: customer_unique_id | D3: Đặc tả trường customer_unique_id của bảng Customers | E3: Text | F3: Text | G3: Yes | H3: FK | I3: Customers.customer_unique_id | K3: Phải tồn tại trong Customers.customer_unique_id | L3: Allow/derive theo quy tắc | M3: Giữ nguyên/chuẩn hóa ETL | N3: customer_unique_id | O3: Olist structure
A4: Customers | B4: customer_zip_code_prefix | C4: customer_zip_code_prefix | D4: Đặc tả trường customer_zip_code_prefix của bảng Customers | E4: Text | F4: Text | G4: Conditional | H4: Attribute | K4: Theo kiểu dữ liệu | L4: Allow/derive theo quy tắc | M4: Giữ nguyên/chuẩn hóa ETL | N4: customer_zip_code_prefix | O4: Olist structure
A5: Customers | B5: customer_city | C5: customer_city | D5: Đặc tả trường customer_city của bảng Customers | E5: Text | F5: Text | G5: Conditional | H5: Attribute | K5: Theo kiểu dữ liệu | L5: Allow/derive theo quy tắc | M5: Giữ nguyên/chuẩn hóa ETL | N5: customer_city | O5: Olist structure
A6: Customers | B6: customer_state | C6: customer_state | D6: Đặc tả trường customer_state của bảng Customers | E6: Text | F6: Text | G6: Conditional | H6: Attribute | K6: Theo kiểu dữ liệu | L6: Allow/derive theo quy tắc | M6: Giữ nguyên/chuẩn hóa ETL | N6: customer_state | O6: Olist structure
A7: Customers | B7: CustomerName | C7: CustomerName | D7: Đặc tả trường CustomerName của bảng Customers | E7: Text | F7: Text | G7: Conditional | H7: Attribute | K7: Theo kiểu dữ liệu | L7: Allow/derive theo quy tắc | M7: Giữ nguyên/chuẩn hóa ETL | N7: CustomerName | O7: Olist structure
A8: Customers | B8: Region | C8: Region | D8: Đặc tả trường Region của bảng Customers | E8: Text | F8: Text | G8: Conditional | H8: Attribute | K8: Theo kiểu dữ liệu | L8: Allow/derive theo quy tắc | M8: Giữ nguyên/chuẩn hóa ETL | N8: Region | O8: Olist structure
A9: Customers | B9: ProvinceCity | C9: ProvinceCity | D9: Đặc tả trường ProvinceCity của bảng Customers | E9: Text | F9: Text | G9: Conditional | H9: Attribute | K9: Theo kiểu dữ liệu | L9: Allow/derive theo quy tắc | M9: Giữ nguyên/chuẩn hóa ETL | N9: ProvinceCity | O9: Olist structure
A10: Customers | B10: Email | C10: Email | D10: Đặc tả trường Email của bảng Customers | E10: Text | F10: Text | G10: Conditional | H10: Attribute | K10: Theo kiểu dữ liệu | L10: Allow/derive theo quy tắc | M10: Giữ nguyên/chuẩn hóa ETL | N10: Email | O10: Olist structure
A11: Customers | B11: Phone | C11: Phone | D11: Đặc tả trường Phone của bảng Customers | E11: Text | F11: Text | G11: Conditional | H11: Attribute | K11: Theo kiểu dữ liệu | L11: Allow/derive theo quy tắc | M11: Giữ nguyên/chuẩn hóa ETL | N11: Phone | O11: Olist structure
A12: Customers | B12: RegisteredDate | C12: RegisteredDate | D12: Đặc tả trường RegisteredDate của bảng Customers | E12: Datetime | F12: yyyy-mm-dd hh:mm:ss | G12: Conditional | H12: Attribute | K12: Theo kiểu dữ liệu | L12: Allow/derive theo quy tắc | M12: Giữ nguyên/chuẩn hóa ETL | N12: RegisteredDate | O12: Olist structure
A13: Customers | B13: owner_id | C13: Nhân viên phụ trách | D13: Đặc tả trường owner_id của bảng Customers | E13: Text | F13: Text | G13: Yes | H13: FK | I13: Employees.employee_id | K13: Phải tồn tại trong Employees.employee_id | L13: Allow/derive theo quy tắc | M13: Tính toán hoặc sinh theo SRS | N13: owner_id | O13: SRS/VN-added
A14: Customers | B14: CustomerStatus | C14: CustomerStatus | D14: Đặc tả trường CustomerStatus của bảng Customers | E14: Text | F14: Text | G14: Conditional | H14: Attribute | K14: Theo kiểu dữ liệu | L14: Allow/derive theo quy tắc | M14: Tính toán hoặc sinh theo SRS | N14: CustomerStatus | O14: SRS/VN-added
A15: Customers | B15: CustomerSegment | C15: Phân khúc khách hàng | D15: Đặc tả trường CustomerSegment của bảng Customers | E15: Text | F15: Text | G15: Conditional | H15: Attribute | K15: Theo kiểu dữ liệu | L15: Allow/derive theo quy tắc | M15: Tính toán hoặc sinh theo SRS | N15: CustomerSegment | O15: SRS/VN-added
A16: Products | B16: product_id | C16: product_id | D16: Đặc tả trường product_id của bảng Products | E16: Text | F16: Text | G16: Yes | H16: PK | I16: Products.product_id | K16: Không trùng và không rỗng | L16: Reject | M16: Giữ nguyên/chuẩn hóa ETL | N16: product_id | O16: Olist structure
A17: Products | B17: product_category_name | C17: product_category_name | D17: Đặc tả trường product_category_name của bảng Products | E17: Text | F17: Text | G17: Conditional | H17: Attribute | K17: Theo kiểu dữ liệu | L17: Allow/derive theo quy tắc | M17: Giữ nguyên/chuẩn hóa ETL | N17: product_category_name | O17: Olist structure
A18: Products | B18: product_name_lenght | C18: product_name_lenght | D18: Đặc tả trường product_name_lenght của bảng Products | E18: Text | F18: Text | G18: Conditional | H18: Attribute | K18: Theo kiểu dữ liệu | L18: Allow/derive theo quy tắc | M18: Giữ nguyên/chuẩn hóa ETL | N18: product_name_lenght | O18: Olist structure
A19: Products | B19: product_description_lenght | C19: product_description_lenght | D19: Đặc tả trường product_description_lenght của bảng Products | E19: Text | F19: Text | G19: Conditional | H19: Attribute | K19: Theo kiểu dữ liệu | L19: Allow/derive theo quy tắc | M19: Giữ nguyên/chuẩn hóa ETL | N19: product_description_lenght | O19: Olist structure
A20: Products | B20: product_photos_qty | C20: product_photos_qty | D20: Đặc tả trường product_photos_qty của bảng Products | E20: Text | F20: Text | G20: Conditional | H20: Attribute | K20: Theo kiểu dữ liệu | L20: Allow/derive theo quy tắc | M20: Giữ nguyên/chuẩn hóa ETL | N20: product_photos_qty | O20: Olist structure
A21: Products | B21: product_weight_g | C21: product_weight_g | D21: Đặc tả trường product_weight_g của bảng Products | E21: Number | F21: Number | G21: Conditional | H21: Attribute | K21: Theo kiểu dữ liệu | L21: Allow/derive theo quy tắc | M21: Giữ nguyên/chuẩn hóa ETL | N21: product_weight_g | O21: Olist structure
A22: Products | B22: product_length_cm | C22: product_length_cm | D22: Đặc tả trường product_length_cm của bảng Products | E22: Number | F22: Number | G22: Conditional | H22: Attribute | K22: Theo kiểu dữ liệu | L22: Allow/derive theo quy tắc | M22: Giữ nguyên/chuẩn hóa ETL | N22: product_length_cm | O22: Olist structure
A23: Products | B23: product_height_cm | C23: product_height_cm | D23: Đặc tả trường product_height_cm của bảng Products | E23: Number | F23: Number | G23: Conditional | H23: Attribute | K23: Theo kiểu dữ liệu | L23: Allow/derive theo quy tắc | M23: Giữ nguyên/chuẩn hóa ETL | N23: product_height_cm | O23: Olist structure
A24: Products | B24: product_width_cm | C24: product_width_cm | D24: Đặc tả trường product_width_cm của bảng Products | E24: Number | F24: Number | G24: Conditional | H24: Attribute | K24: Theo kiểu dữ liệu | L24: Allow/derive theo quy tắc | M24: Giữ nguyên/chuẩn hóa ETL | N24: product_width_cm | O24: Olist structure
A25: Products | B25: Description | C25: Description | D25: Đặc tả trường Description của bảng Products | E25: Text | F25: Text | G25: Conditional | H25: Attribute | K25: Theo kiểu dữ liệu | L25: Allow/derive theo quy tắc | M25: Giữ nguyên/chuẩn hóa ETL | N25: Description | O25: Olist structure
A26: Products | B26: ProductCategory | C26: ProductCategory | D26: Đặc tả trường ProductCategory của bảng Products | E26: Text | F26: Text | G26: Conditional | H26: Attribute | K26: Theo kiểu dữ liệu | L26: Allow/derive theo quy tắc | M26: Giữ nguyên/chuẩn hóa ETL | N26: ProductCategory | O26: Olist structure
A27: Products | B27: ListPrice | C27: Giá niêm yết | D27: Giá bán tham chiếu trung bình của sản phẩm, tính từ chi tiết đơn hàng | E27: Number | F27: #,##0 "₫" | G27: Yes | H27: Attribute | J27: Giá trị >= 0 | K27: Phải là số không âm | L27: Không để trống; 0 nếu chưa có giao dịch | M27: AVG OderItems.price theo product_id | N27: 420000 | O27: Derived/VN-added
A28: Products | B28: Currency | C28: Đơn vị tiền tệ | D28: Đơn vị tiền tệ áp dụng cho giá niêm yết sản phẩm | E28: Text | F28: 3 | G28: Yes | H28: Attribute | J28: VNĐ | K28: Giá trị phải bằng "VNĐ" | L28: Mặc định VNĐ | M28: Gán cố định "VNĐ" | N28: VNĐ | O28: VN-added
A29: Products | B29: ProductStatus | C29: Trạng thái sản phẩm | D29: Trạng thái đang kinh doanh hoặc ngừng kinh doanh của sản phẩm | E29: Text | F29: 20 | G29: Yes | H29: Attribute | J29: Active; Inactive | K29: Chỉ nhận Active hoặc Inactive | L29: Mặc định Active | M29: Gán "Active" cho dữ liệu demo | N29: Active | O29: VN-added
A30: Orders | B30: order_id | C30: order_id | D30: Đặc tả trường order_id của bảng Orders | E30: Text | F30: Text | G30: Yes | H30: PK/FK | I30: Orders.order_id | K30: Không trùng và không rỗng | L30: Reject | M30: Giữ nguyên/chuẩn hóa ETL | N30: order_id | O30: Olist structure
A31: Orders | B31: customer_id | C31: customer_id | D31: Đặc tả trường customer_id của bảng Orders | E31: Text | F31: Text | G31: Yes | H31: PK | K31: Không trùng và không rỗng | L31: Reject | M31: Giữ nguyên/chuẩn hóa ETL | N31: customer_id | O31: Olist structure
A32: Orders | B32: order_status | C32: order_status | D32: Đặc tả trường order_status của bảng Orders | E32: Text | F32: Text | G32: Conditional | H32: Attribute | J32: delivered,canceled,returned,processing | K32: Theo kiểu dữ liệu | L32: Allow/derive theo quy tắc | M32: Giữ nguyên/chuẩn hóa ETL | N32: order_status | O32: Olist structure
A33: Orders | B33: order_purchase_timestamp | C33: order_purchase_timestamp | D33: Đặc tả trường order_purchase_timestamp của bảng Orders | E33: Datetime | F33: yyyy-mm-dd hh:mm:ss | G33: Conditional | H33: Attribute | K33: Theo kiểu dữ liệu | L33: Allow/derive theo quy tắc | M33: Giữ nguyên/chuẩn hóa ETL | N33: order_purchase_timestamp | O33: Olist structure
A34: Orders | B34: order_approved_at | C34: order_approved_at | D34: Đặc tả trường order_approved_at của bảng Orders | E34: Datetime | F34: yyyy-mm-dd hh:mm:ss | G34: Conditional | H34: Attribute | K34: Theo kiểu dữ liệu | L34: Allow/derive theo quy tắc | M34: Giữ nguyên/chuẩn hóa ETL | N34: order_approved_at | O34: Olist structure
A35: Orders | B35: order_delivered_carrier_date | C35: order_delivered_carrier_date | D35: Đặc tả trường order_delivered_carrier_date của bảng Orders | E35: Datetime | F35: yyyy-mm-dd hh:mm:ss | G35: Conditional | H35: Attribute | K35: Theo kiểu dữ liệu | L35: Allow/derive theo quy tắc | M35: Giữ nguyên/chuẩn hóa ETL | N35: order_delivered_carrier_date | O35: Olist structure
A36: Orders | B36: order_delivered_customer_date | C36: order_delivered_customer_date | D36: Đặc tả trường order_delivered_customer_date của bảng Orders | E36: Datetime | F36: yyyy-mm-dd hh:mm:ss | G36: Conditional | H36: Attribute | K36: Theo kiểu dữ liệu | L36: Allow/derive theo quy tắc | M36: Giữ nguyên/chuẩn hóa ETL | N36: order_delivered_customer_date | O36: Olist structure
A37: Orders | B37: order_estimated_delivery_date | C37: order_estimated_delivery_date | D37: Đặc tả trường order_estimated_delivery_date của bảng Orders | E37: Datetime | F37: yyyy-mm-dd hh:mm:ss | G37: Conditional | H37: Attribute | K37: Theo kiểu dữ liệu | L37: Allow/derive theo quy tắc | M37: Giữ nguyên/chuẩn hóa ETL | N37: order_estimated_delivery_date | O37: Olist structure
A38: Orders | B38: CustomerID | C38: CustomerID | D38: Đặc tả trường CustomerID của bảng Orders | E38: Text | F38: Text | G38: Conditional | H38: FK | I38: Customers.customer_unique_id | K38: Phải tồn tại trong Customers.customer_unique_id | L38: Allow/derive theo quy tắc | M38: Giữ nguyên/chuẩn hóa ETL | N38: CustomerID | O38: Olist structure
A39: Orders | B39: SalesChannel | C39: SalesChannel | D39: Đặc tả trường SalesChannel của bảng Orders | E39: Text | F39: Text | G39: Conditional | H39: Attribute | K39: Theo kiểu dữ liệu | L39: Allow/derive theo quy tắc | M39: Giữ nguyên/chuẩn hóa ETL | N39: SalesChannel | O39: Olist structure
A40: Orders | B40: PaymentMethod | C40: PaymentMethod | D40: Đặc tả trường PaymentMethod của bảng Orders | E40: Text | F40: Text | G40: Conditional | H40: Attribute | K40: Theo kiểu dữ liệu | L40: Allow/derive theo quy tắc | M40: Giữ nguyên/chuẩn hóa ETL | N40: PaymentMethod | O40: Olist structure
...

Sheet Employees
A1: employee_id | B1: employee_name | C1: department | D1: email | E1: phone | F1: region_scope | G1: status | H1: start_date
A2: EMP001 | B2: Nguyễn Minh Anh | C2: Kinh doanh | D2: minhanh@demo.vn | E2: 0901 000 001 | F2: Miền Bắc | G2: Active | H2: 45292
A3: EMP002 | B3: Trần Quốc Bảo | C3: Kinh doanh | D3: quocbao@demo.vn | E3: 0901 000 002 | F3: Miền Bắc | G3: Active | H3: 45323
A4: EMP003 | B4: Lê Thu Hà | C4: Chăm sóc khách hàng | D4: thuha@demo.vn | E4: 0901 000 003 | F4: Miền Trung | G4: Active | H4: 45352
A5: EMP004 | B5: Phạm Gia Huy | C5: Kinh doanh | D5: giahuy@demo.vn | E5: 0901 000 004 | F5: Miền Trung | G5: Active | H5: 45383
A6: EMP005 | B6: Võ Ngọc Lan | C6: Chăm sóc khách hàng | D6: ngoclan@demo.vn | E6: 0901 000 005 | F6: Miền Nam | G6: Active | H6: 45413
A7: EMP006 | B7: Bùi Thanh Nam | C7: Kinh doanh | D7: thanhnam@demo.vn | E7: 0901 000 006 | F7: Miền Nam | G7: Active | H7: 45444
A8: EMP007 | B8: Đặng Minh Phúc | C8: Marketing | D8: minhphuc@demo.vn | E8: 0901 000 007 | F8: Toàn quốc | G8: Active | H8: 45474
A9: EMP008 | B9: Hoàng Thu Trang | C9: Marketing | D9: thutrang@demo.vn | E9: 0901 000 008 | F9: Toàn quốc | G9: Active | H9: 45505

Sheet Interactions
A1: interaction_id | B1: customer_unique_id | C1: product_id | D1: interaction_type | E1: interaction_timestamp | F1: channel | G1: session_id | H1: campaign_id | I1: interaction_value | J1: interaction_result
A2: INT00001 | B2: KH0001 | C2: SP012 | D2: search | E2: 46056.655 | F2: Ứng dụng | G2: SES000101 | H2: CAM002 | I2: 1 | J2: results_viewed
A3: INT00002 | B3: KH0001 | C3: SP034 | D3: checkout_started | E3: 45959.32 | F3: Email | G3: SES000102 | I3: 4 | J3: started
A4: INT00003 | B4: KH0001 | C4: SP008 | D4: chat | E4: 45940.345 | F4: Chat | G4: SES000103 | I4: 3 | J4: contacted
A5: INT00004 | B5: KH0001 | C5: SP005 | D5: add_to_cart | E5: 45501.566 | F5: Website | G5: SES000104 | H5: CAM001 | I5: 3 | J5: added
A6: INT00005 | B6: KH0001 | C6: SP021 | D6: email_open | E6: 45848.54 | F6: Ứng dụng | G6: SES000105 | I6: 1 | J6: opened
A7: INT00006 | B7: KH0001 | C7: SP026 | D7: product_view | E7: 46219.744 | F7: Email | G7: SES000106 | I7: 1 | J7: viewed
A8: INT00007 | B8: KH0002 | C8: SP035 | D8: add_to_cart | E8: 46189.58 | F8: Email | G8: SES000201 | H8: CAM003 | I8: 3 | J8: added
A9: INT00008 | B9: KH0002 | C9: SP004 | D9: email_open | E9: 45551.078 | F9: Chat | G9: SES000202 | I9: 1 | J9: opened
A10: INT00009 | B10: KH0002 | C10: SP028 | D10: product_view | E10: 45601.511 | F10: Website | G10: SES000203 | I10: 1 | J10: viewed
A11: INT00010 | B11: KH0002 | C11: SP040 | D11: wishlist | E11: 46128.362 | F11: Ứng dụng | G11: SES000204 | H11: CAM002 | I11: 2 | J11: saved
A12: INT00011 | B12: KH0002 | C12: SP001 | D12: email_click | E12: 45690.682 | F12: Email | G12: SES000205 | I12: 2 | J12: clicked
A13: INT00012 | B13: KH0002 | C13: SP035 | D13: search | E13: 45820.522 | F13: Chat | G13: SES000206 | I13: 1 | J13: results_viewed
A14: INT00013 | B14: KH0003 | C14: SP026 | D14: wishlist | E14: 45825.018 | F14: Chat | G14: SES000301 | H14: CAM004 | I14: 2 | J14: saved
A15: INT00014 | B15: KH0003 | C15: SP025 | D15: email_click | E15: 45453.639 | F15: Website | G15: SES000302 | I15: 2 | J15: clicked
A16: INT00015 | B16: KH0003 | C16: SP010 | D16: search | E16: 45397.388 | F16: Ứng dụng | G16: SES000303 | I16: 1 | J16: results_viewed
A17: INT00016 | B17: KH0003 | C17: SP023 | D17: checkout_started | E17: 45321.027 | F17: Email | G17: SES000304 | H17: CAM003 | I17: 4 | J17: started
A18: INT00017 | B18: KH0003 | C18: SP016 | D18: chat | E18: 46216.791 | F18: Chat | G18: SES000305 | I18: 3 | J18: contacted
A19: INT00018 | B19: KH0003 | C19: SP006 | D19: add_to_cart | E19: 45678.094 | F19: Website | G19: SES000306 | I19: 3 | J19: added
A20: INT00019 | B20: KH0004 | C20: SP024 | D20: checkout_started | E20: 45478.519 | F20: Website | G20: SES000401 | H20: CAM001 | I20: 4 | J20: started
A21: INT00020 | B21: KH0004 | C21: SP025 | D21: chat | E21: 45408.982 | F21: Ứng dụng | G21: SES000402 | I21: 3 | J21: contacted
A22: INT00021 | B22: KH0004 | C22: SP016 | D22: add_to_cart | E22: 45466.344 | F22: Email | G22: SES000403 | I22: 3 | J22: added
A23: INT00022 | B23: KH0004 | C23: SP018 | D23: email_open | E23: 45477.885 | F23: Chat | G23: SES000404 | H23: CAM004 | I23: 1 | J23: opened
A24: INT00023 | B24: KH0004 | C24: SP027 | D24: product_view | E24: 45961.945 | F24: Website | G24: SES000405 | I24: 1 | J24: viewed
A25: INT00024 | B25: KH0004 | C25: SP040 | D25: wishlist | E25: 45695.635 | F25: Ứng dụng | G25: SES000406 | I25: 2 | J25: saved
A26: INT00025 | B26: KH0005 | C26: SP009 | D26: email_open | E26: 45535.556 | F26: Ứng dụng | G26: SES000501 | H26: CAM002 | I26: 1 | J26: opened
A27: INT00026 | B27: KH0005 | C27: SP040 | D27: product_view | E27: 46146.118 | F27: Email | G27: SES000502 | I27: 1 | J27: viewed
A28: INT00027 | B28: KH0005 | C28: SP014 | D28: wishlist | E28: 45500.956 | F28: Chat | G28: SES000503 | I28: 2 | J28: saved
A29: INT00028 | B29: KH0005 | C29: SP034 | D29: email_click | E29: 46001.442 | F29: Website | G29: SES000504 | H29: CAM001 | I29: 2 | J29: clicked
A30: INT00029 | B30: KH0005 | C30: SP001 | D30: search | E30: 45923.803 | F30: Ứng dụng | G30: SES000505 | I30: 1 | J30: results_viewed
A31: INT00030 | B31: KH0005 | C31: SP028 | D31: checkout_started | E31: 45464.012 | F31: Email | G31: SES000506 | I31: 4 | J31: started
A32: INT00031 | B32: KH0006 | C32: SP016 | D32: email_click | E32: 45765.665 | F32: Email | G32: SES000601 | H32: CAM003 | I32: 2 | J32: clicked
A33: INT00032 | B33: KH0006 | C33: SP035 | D33: search | E33: 45942.986 | F33: Chat | G33: SES000602 | I33: 1 | J33: results_viewed
A34: INT00033 | B34: KH0006 | C34: SP014 | D34: checkout_started | E34: 46216.396 | F34: Website | G34: SES000603 | I34: 4 | J34: started
A35: INT00034 | B35: KH0006 | C35: SP019 | D35: chat | E35: 46145.375 | F35: Ứng dụng | G35: SES000604 | H35: CAM002 | I35: 3 | J35: contacted
A36: INT00035 | B36: KH0006 | C36: SP037 | D36: add_to_cart | E36: 45921.28 | F36: Email | G36: SES000605 | I36: 3 | J36: added
A37: INT00036 | B37: KH0006 | C37: SP006 | D37: email_open | E37: 46093.484 | F37: Chat | G37: SES000606 | I37: 1 | J37: opened
A38: INT00037 | B38: KH0007 | C38: SP035 | D38: chat | E38: 45687.291 | F38: Chat | G38: SES000701 | H38: CAM004 | I38: 3 | J38: contacted
A39: INT00038 | B39: KH0007 | C39: SP029 | D39: add_to_cart | E39: 45714.045 | F39: Website | G39: SES000702 | I39: 3 | J39: added
A40: INT00039 | B40: KH0007 | C40: SP011 | D40: email_open | E40: 45358.368 | F40: Ứng dụng | G40: SES000703 | I40: 1 | J40: opened
...

Sheet Campaigns
A1: campaign_id | B1: campaign_name | C1: campaign_type | D1: start_date | E1: end_date | F1: channel | G1: target_segment | H1: status | I1: budget_vnd
A2: CAM001 | B2: Khuyến mãi Tết | C2: Promotion | D2: 45292 | E2: 45352 | F2: Email/App | G2: Khách hàng hiện hữu | H2: Completed | I2: 80000000
A3: CAM002 | B3: Hè năng động | C3: Seasonal | D3: 45444 | E3: 45535 | F3: Website/App | G3: Khách hàng trẻ | H3: Completed | I3: 60000000
A4: CAM003 | B4: Ngày hội thành viên | C4: Loyalty | D4: 45747 | E4: 45838 | F4: Email/App | G4: Khách mua lặp lại | H4: Completed | I4: 70000000
A5: CAM004 | B5: Ưu đãi cuối năm | C5: Promotion | D5: 45991 | E5: 46081 | F5: Đa kênh | G5: Khách tiềm năng | H5: Active | I5: 100000000

Sheet CustomerAnalytics
A1: AnalysisDate | B1: CustomerID | C1: OwnerID | D1: RecencyDays | E1: Frequency | F1: Monetary | G1: AOV | H1: AvgPurchaseCycleDays | I1: AvgReviewScore | J1: InteractionScore | K1: RScore | L1: FScore | M1: MScore | N1: PotentialScore | O1: Segment | P1: ModelStatus
A2: 46247 | B2: KH0001 | C2: =IFERROR(VLOOKUP(B2,Customers!$B$2:$L$81,11,FALSE),"") -> EMP001 | D2: =IFERROR(__xludf.DUMMYFUNCTION("IFERROR(A2-MAX(FILTER(Orders!$D$2:$D$201,Orders!$I$2:$I$201=B2,Orders!$T$2:$T$201=TRUE)),"""")"),68.35771990740614) -> 68.35772 | E2: =COUNTIFS(Orders!$I$2:$I$201,B2,Orders!$T$2:$T$201,TRUE) -> 2 | F2: =SUMIFS(Orders!$R$2:$R$201,Orders!$I$2:$I$201,B2,Orders!$T$2:$T$201,TRUE) -> 2661000 | G2: =IFERROR(F2/E2,0) -> 1330500 | H2: =IFERROR(__xludf.DUMMYFUNCTION("IF(E2<2,"""",IFERROR((MAX(FILTER(Orders!$D$2:$D$201,Orders!$I$2:$I$201=B2,Orders!$T$2:$T$201=TRUE))-MIN(FILTER(Orders!$D$2:$D$201,Orders!$I$2:$I$201=B2,Orders!$T$2:$T$201=TRUE)))/(E2-1),""""))"),561.5618518518531) -> 561.56185 | I2: =IFERROR(AVERAGEIF(Reviews!$H$2:$H$142,B3,Reviews!$C$2:$C$142),"") -> 3.75 | J2: =SUMIF(Interactions!$B$2:$B$481,B2,Interactions!$I$2:$I$481) -> 13 | K2: =IF(D2="","",MAX(1,MIN(5,6-ROUNDUP(PERCENTRANK($D$2:$D$81,D2)*4+1,0)))) -> 4 | L2: =MAX(1,MIN(5,ROUNDUP(PERCENTRANK($E$2:$E$81,E2)*4+1,0))) -> 4 | M2: =MAX(1,MIN(5,ROUNDUP(PERCENTRANK($F$2:$F$81,F2)*4+1,0))) -> 4 | N2: =IF(K2="","",ROUND((K2*35+L2*30+M2*20+(1+4*(J2-MIN($J$2:$J$81))/MAX(1,MAX($J$2:$J$81)-MIN($J$2:$J$81)))*15)/5,1)) -> 78.2 | O2: =IF(N2="","Chưa đủ dữ liệu",IF(N2>=80,"Tiềm năng cao",IF(N2>=60,"Tiềm năng","Thông thường"))) -> Tiềm năng | P2: Rule-based prototype
